Workbook

Sheet Summary
A1: Line-Energy Solar Designer | B1: v0.19.0-draft
A2: Item | B2: Value | C2: Unit | D2: Status / Note
A3: Overall compatibility | B3: =Compatibility!B8 | D3: PASS / FAIL / VERIFY
A4: PV electrical status | B4: =Results!B25 | D4: From Results
A5: Battery status | B5: =Compatibility!B6 | D5: From Compatibility
A6: Datasheet completeness | B6: =Compatibility!B7 | D6: From Compatibility
A7: Inverter | B7: =Inputs!B3 | D7: Selected model
A8: Panel | B8: =Inputs!B4 | D8: Selected model
A9: Battery | B9: =Inputs!B9 | D9: Selected model
A10: Panels per string | B10: =Inputs!B7 | C10: pcs | D10: Selected value
A11: Recommended string range | B11: =Results!B21 | C11: pcs | D11: Calculated range
A12: Battery total energy | B12: =Results!B29 | C12: kWh | D12: Nominal energy
A13: Roof type | B13: =Inputs!B11 | D13: Selected roof
A14: Total panels | B14: =Inputs!B12 | C14: pcs | D14: Mounting input
A15: Rows | B15: =Mounting!B5 | C15: rows | D15: Mounting calculation
A16: Rails | B16: =Mounting!B13 | C16: pcs | D16: Mounting calculation
A17: End clamps | B17: =Mounting!B15 | C17: pcs | D17: Mounting calculation
A18: Middle clamps | B18: =Mounting!B16 | C18: pcs | D18: Mounting calculation
A19: Grounding clips | B19: =Mounting!B18 | C19: pcs | D19: Mounting calculation
A20: Cable clips | B20: =Mounting!B19 | C20: pcs | D20: Mounting calculation
A21: Equipment list items | B21: =COUNTA(Equipment!A2:A35) | C21: items | D21: Generated equipment output
A22: Protection items | B22: =COUNTA(CableProtection!A2:A32) | C22: items | D22: Generated protection output
A23: DC cable section | B23: =CableProtection!B15 | C23: mm2 | D23: Starter sizing
A24: AC cable section | B24: =CableProtection!B19 | C24: mm2 | D24: Starter sizing
A25: Battery cable section | B25: =CableProtection!B24 | C25: mm2 | D25: Starter sizing
A26: SPD recommendation | B26: =CableProtection!B28 | D26: Starter protection selection
A27: Earthing system | B27: =CableProtection!B29 | D27: Selected AC earthing system
A28: Cable derating factor | B28: =CableProtection!B30 | C28: factor | D28: Grouping x ambient factors
A29: Bulk scenarios | B29: =COUNTA(BulkCompatibility!A2:A100) | C29: rows | D29: Mass compatibility table
A30: Bulk PASS | B30: =COUNTIF(BulkCompatibility!L2:L100,"PASS") | C30: rows | D30: Bulk compatibility count
A31: Bulk FAIL | B31: =COUNTIF(BulkCompatibility!L2:L100,"FAIL") | C31: rows | D31: Bulk compatibility count
A32: Bulk VERIFY | B32: =COUNTIF(BulkCompatibility!L2:L100,"VERIFY") | C32: rows | D32: Bulk compatibility count
A33: Region | B33: =Economics!B2 | D33: Economics input
A34: Annual generation | B34: =Economics!B8 | C34: kWh/year | D34: Regional yield estimate
A35: Annual savings | B35: =Economics!B12 | C35: RUB/year | D35: Self-consumption plus export
A36: Simple payback | B36: =Economics!B13 | C36: years | D36: Installed cost / annual savings
A37: Tariff source status | B37: =Economics!B15 | D37: Must be verified
A38: Monthly consumption | B38: =Inputs!B29 | C38: kWh/month | D38: Customer input
A39: Target coverage | B39: =Inputs!B30 | C39: % | D39: Option sizing target
A40: Recommended standard size | B40: =SystemOptions!H3 | C40: kWp | D40: SystemOptions
...

Sheet Inputs
A1: Line-Energy Solar Calculator | B1: v0.19.0-draft
A2: Input | B2: Value | C2: Unit | D2: Notes
A3: Inverter model | B3: SUN-8K-SG01LP1-EU | D3: Choose from dropdown
A4: Panel model | B4: JKM575N-72HL4-V | D4: Choose from dropdown
A5: Minimum ambient temperature | B5: -10 | C5: C | D5: Used for cold Voc check
A6: Maximum cell temperature | B6: 70 | C6: C | D6: Used for hot Vmp check
A7: Panels per string | B7: 8 | C7: pcs | D7: Series modules in one string
A8: Strings per MPPT | B8: 1 | C8: pcs | D8: Parallel strings on one tracker
A9: Battery model | B9: US5000 | D9: Choose from dropdown
A10: Battery quantity | B10: 2 | C10: pcs | D10: Used for total battery capacity
A11: Roof type | B11: Metal tile | D11: Choose from dropdown
A12: Total panels | B12: 16 | C12: pcs | D12: Used for mounting quantity calculation
A13: Panels per row | B13: 8 | C13: pcs | D13: Used for row and clamp calculation
A14: Rail stock length | B14: 4.2 | C14: m | D14: Used for rail connector estimate
A15: Rail length per panel | B15: 1.15 | C15: m | D15: Starter assumption; adjust by panel orientation
A16: Mounting reserve | B16: 10 | C16: % | D16: Extra quantity reserve
A17: DC cable route length | B17: 30 | C17: m | D17: One-way route length estimate
A18: AC cable route length | B18: 20 | C18: m | D18: One-way route length estimate
A19: Grounding cable route length | B19: 25 | C19: m | D19: Grounding route length estimate
A20: Installation method | B20: Open air | D20: Used for cable derating notes
A21: Cable grouping derating | B21: 1 | C21: factor | D21: Starter factor; adjust by local rules
A22: Ambient temperature derating | B22: 1 | C22: factor | D22: Starter factor; adjust by local rules
A23: Lightning protection system | B23: No external LPS | D23: Used for SPD type suggestion
A24: AC earthing system | B24: TN-S | D24: Used for earthing checklist
A25: Region / tariff zone | B25: Moscow starter | D25: Choose from tariff database
A26: Self-consumption share | B26: 70 | C26: % | D26: Share of generation consumed on site
A27: Installed system cost | B27: 800000 | C27: RUB | D27: Used for simple payback estimate
A28: Tariff source status | B28: VERIFY | D28: Tariffs must be checked for exact supplier/date
A29: Monthly consumption | B29: 1000 | C29: kWh/month | D29: Customer monthly electricity consumption
A30: Target coverage | B30: 70 | C30: % | D30: Recommended options cover this share of annual consumption
A31: Tariff mode | B31: Single-rate | D31: Single-rate or Day-night comparison
A32: Day consumption share | B32: 65 | C32: % | D32: Used for day-night tariff comparison
A33: Day tariff | B33: 9.8 | C33: RUB/kWh | D33: Starter day tariff; verify supplier/date
A34: Night tariff | B34: 3.5 | C34: RUB/kWh | D34: Starter night tariff; verify supplier/date
A35: Design note | B35: Starter calculation only | D35: Verify datasheets and mounting manuals before commercial use

Sheet Results
A1: Result | B1: Value | C1: Unit | D1: Formula / meaning
A2: Inverter model | B2: =Inputs!B3 | D2: From Inputs
A3: Panel model | B3: =Inputs!B4 | D3: From Inputs
A4: Panels per string | B4: =Inputs!B7 | C4: pcs | D4: From Inputs
A5: Strings per MPPT | B5: =Inputs!B8 | C5: pcs | D5: From Inputs
A6: Max PV voltage | B6: =INDEX(Inverters!G:G,MATCH(B2,Inverters!C:C,0)) | C6: V | D6: Inverter absolute PV voltage limit
A7: MPPT min voltage | B7: =INDEX(Inverters!I:I,MATCH(B2,Inverters!C:C,0)) | C7: V | D7: Inverter lower MPPT voltage
A8: MPPT max voltage | B8: =INDEX(Inverters!J:J,MATCH(B2,Inverters!C:C,0)) | C8: V | D8: Inverter upper MPPT voltage
A9: Max input current per MPPT | B9: =INDEX(Inverters!M:M,MATCH(B2,Inverters!C:C,0)) | C9: A | D9: Inverter current limit
A10: Panel Voc STC | B10: =INDEX(Panels!G:G,MATCH(B3,Panels!C:C,0)) | C10: V | D10: Open-circuit voltage at STC
A11: Panel Vmp STC | B11: =INDEX(Panels!E:E,MATCH(B3,Panels!C:C,0)) | C11: V | D11: Voltage at maximum power at STC
A12: Panel Imp STC | B12: =INDEX(Panels!F:F,MATCH(B3,Panels!C:C,0)) | C12: A | D12: Current at maximum power at STC
A13: Panel voltage temperature coefficient | B13: =INDEX(Panels!J:J,MATCH(B3,Panels!C:C,0)) | C13: %/C | D13: Preliminary voltage correction
A14: Cold Voc per panel | B14: =B10*(1+(B13/100)*(Inputs!B5-25)) | C14: V | D14: Voc at minimum temperature
A15: Hot Vmp per panel | B15: =B11*(1+(B13/100)*(Inputs!B6-25)) | C15: V | D15: Vmp at maximum cell temperature
A16: Cold string Voc | B16: =B14*B4 | C16: V | D16: Cold Voc per panel x panels per string
A17: Hot string Vmp | B17: =B15*B4 | C17: V | D17: Hot Vmp per panel x panels per string
A18: Minimum panels per string by MPPT | B18: =ROUNDUP(B7/B15,0) | C18: pcs | D18: Ceiling of MPPT min / hot Vmp per panel
A19: Maximum panels per string by MPPT | B19: =ROUNDDOWN(B8/B15,0) | C19: pcs | D19: Floor of MPPT max / hot Vmp per panel
A20: Maximum panels per string by PV voltage | B20: =ROUNDDOWN(B6/B14,0) | C20: pcs | D20: Floor of max PV voltage / cold Voc per panel
A21: Recommended panels per string range | B21: =B18&" - "&MIN(B19,B20) | C21: pcs | D21: Minimum to safest maximum
A22: MPPT operating check | B22: =IF(AND(B17>=B7,B17<=B8),"PASS","FAIL") | D22: Hot Vmp must stay inside MPPT window
A23: Max voltage check | B23: =IF(B16<B6,"PASS","FAIL") | D23: Cold Voc must stay below max PV voltage
A24: Current check | B24: =IF(B12*B5<=B9,"PASS","FAIL") | D24: Parallel string current must stay below MPPT current
A25: Overall preliminary status | B25: =IF(AND(B22="PASS",B23="PASS",B24="PASS"),"PASS","FAIL") | D25: All checks must pass
A26: Battery model | B26: =Inputs!B9 | D26: From Inputs
A27: Battery quantity | B27: =Inputs!B10 | C27: pcs | D27: From Inputs
A28: Battery nominal energy | B28: =INDEX(Batteries!E:E,MATCH(B26,Batteries!C:C,0)) | C28: kWh | D28: From Batteries database
A29: Total nominal battery energy | B29: =B27*B28 | C29: kWh | D29: Battery energy x quantity
A30: Battery compatibility note | B30: =INDEX(Batteries!M:M,MATCH(B26,Batteries!C:C,0)) | D30: From Batteries database

Sheet Inverters
A1: brand | B1: series | C1: model | D1: phase | E1: nominal_ac_power_w | F1: max_pv_input_power_w | G1: max_pv_voltage_v | H1: startup_voltage_v | I1: mppt_voltage_min_v | J1: mppt_voltage_max_v | K1: mppt_count | L1: strings_per_mppt | M1: max_input_current_per_mppt_a | N1: max_short_circuit_current_per_mppt_a | O1: battery_nominal_voltage_v | P1: battery_voltage_range_v | Q1: data_status | R1: notes
A2: Anenji | B2: Hybrid | C2: ANJ-3.2KW-24V | D2: single-phase | E2: 3200 | O2: 24 | Q2: model_only_needs_datasheet | R2: Hybrid inverter model candidate; datasheet parameters pending.
A3: Anenji | B3: Hybrid | C3: ANJ-3.6KW-24V | D3: single-phase | E3: 3600 | O3: 24 | Q3: model_only_needs_datasheet | R3: Hybrid inverter model candidate; datasheet parameters pending.
A4: Anenji | B4: Hybrid | C4: ANJ-4.2KW-24V | D4: single-phase | E4: 4200 | O4: 24 | Q4: model_only_needs_datasheet | R4: Hybrid inverter model candidate; datasheet parameters pending.
A5: Anenji | B5: Hybrid | C5: ANJ-6.2KW-48V | D5: single-phase | E5: 6200 | O5: 48 | Q5: model_only_needs_datasheet | R5: Hybrid inverter model candidate; datasheet parameters pending.
A6: Anenji | B6: Hybrid | C6: ANJ-8.2KW-48V | D6: single-phase | E6: 8200 | O6: 48 | Q6: model_only_needs_datasheet | R6: Hybrid inverter model candidate; datasheet parameters pending.
A7: Anenji | B7: Hybrid | C7: ANJ-10.2KW-48V | D7: single-phase | E7: 10200 | O7: 48 | Q7: model_only_needs_datasheet | R7: Hybrid inverter model candidate; datasheet parameters pending.
A8: Anenji | B8: Hybrid | C8: ANJ-11KW-48V | D8: single-phase | E8: 11000 | O8: 48 | Q8: model_only_needs_datasheet | R8: Hybrid inverter model candidate; datasheet parameters pending.
A9: Anenji | B9: Hybrid | C9: ANJ-12KW-48V | D9: single-phase | E9: 12000 | O9: 48 | Q9: model_only_needs_datasheet | R9: Hybrid inverter model candidate; datasheet parameters pending.
A10: Deye | B10: Hybrid LV 24V | C10: SUN-3K-SG04LP1-24-EU | D10: single-phase | E10: 3000 | O10: 24 | Q10: model_only_needs_datasheet | R10: Model list provided by user; datasheet parameters pending.
A11: Deye | B11: Hybrid LV | C11: SUN-3K-SG04LP1-EU | D11: single-phase | E11: 3000 | O11: 48 | Q11: model_only_needs_datasheet | R11: Model list provided by user; datasheet parameters pending.
A12: Deye | B12: Hybrid LV | C12: SUN-3.6K-SG05LP1-EU-AM2-P | D12: single-phase | E12: 3600 | F12: 7200 | G12: 500 | H12: 125 | I12: 150 | J12: 425 | K12: 2 | L12: 2+2 | M12: 32 | N12: 48 | O12: 48 | P12: 40-60 | Q12: datasheet_local_pdf_verified | R12: Local PDF: SUN-_3.6-10_K-SG05LP1-EU-AM2-P_RU.pdf
A13: Deye | B13: Hybrid LV | C13: SUN-5K-SG05LP1-EU-AM2-P | D13: single-phase | E13: 5000 | F13: 10000 | G13: 500 | H13: 125 | I13: 150 | J13: 425 | K13: 2 | L13: 2+2 | M13: 32 | N13: 48 | O13: 48 | P13: 40-60 | Q13: datasheet_local_pdf_verified | R13: Local PDF: SUN-_3.6-10_K-SG05LP1-EU-AM2-P_RU.pdf
A14: Deye | B14: Hybrid LV | C14: SUN-6K-SG05LP1-EU-AM2-P | D14: single-phase | E14: 6000 | F14: 12000 | G14: 500 | H14: 125 | I14: 150 | J14: 425 | K14: 2 | L14: 2+2 | M14: 32 | N14: 48 | O14: 48 | P14: 40-60 | Q14: datasheet_local_pdf_verified | R14: Local PDF: SUN-_3.6-10_K-SG05LP1-EU-AM2-P_RU.pdf
A15: Deye | B15: Hybrid LV | C15: SUN-8K-SG05LP1-EU-AM2-P | D15: single-phase | E15: 8000 | F15: 16000 | G15: 500 | H15: 125 | I15: 150 | J15: 425 | K15: 2 | L15: 2+2 | M15: 32 | N15: 48 | O15: 48 | P15: 40-60 | Q15: datasheet_local_pdf_verified | R15: Local PDF: SUN-_3.6-10_K-SG05LP1-EU-AM2-P_RU.pdf
A16: Deye | B16: Hybrid LV | C16: SUN-10K-SG02LP1-EU-AM3-P | D16: single-phase | E16: 10000 | F16: 20000 | G16: 500 | H16: 125 | I16: 150 | J16: 425 | K16: 3 | L16: 2+2+2 | M16: 32 | N16: 60 | O16: 48 | P16: 40-60 | Q16: datasheet_local_pdf_verified | R16: Local PDF: SUN-_7.6-12_K-SG02LP1-EU-AM2-P_RU.pdf
A17: Deye | B17: Hybrid LV | C17: SUN-12K-SG02LP1-EU-AM3-P | D17: single-phase | E17: 12000 | F17: 24000 | G17: 500 | H17: 125 | I17: 150 | J17: 425 | K17: 3 | L17: 2+2+2 | M17: 32 | N17: 60 | O17: 48 | P17: 40-60 | Q17: datasheet_local_pdf_verified | R17: Local PDF: SUN-_7.6-12_K-SG02LP1-EU-AM2-P_RU.pdf
A18: Deye | B18: Hybrid LV | C18: SUN-14K-SG01LP1-EU-AM3-P | D18: single-phase | E18: 14000 | F18: 28000 | G18: 500 | H18: 125 | I18: 150 | J18: 425 | K18: 3 | L18: 2+2+2 | M18: 36 | N18: 54 | O18: 48 | P18: 40-60 | Q18: datasheet_local_pdf_verified | R18: Local PDF: SUN-_12-18_K-SG01LP1-EU-AM3-P_RU.pdf
A19: Deye | B19: Hybrid LV | C19: SUN-16K-SG01LP1-EU-AM3-P | D19: single-phase | E19: 16000 | F19: 32000 | G19: 500 | H19: 125 | I19: 150 | J19: 425 | K19: 3 | L19: 2+2+2 | M19: 36 | N19: 54 | O19: 48 | P19: 40-60 | Q19: datasheet_local_pdf_verified | R19: Local PDF: SUN-_12-18_K-SG01LP1-EU-AM3-P_RU.pdf
A20: Deye | B20: Hybrid LV | C20: SUN-18K-SG01LP1-EU-AM3-P | D20: single-phase | E20: 18000 | F20: 36000 | G20: 500 | H20: 125 | I20: 150 | J20: 425 | K20: 3 | L20: 2+2+2 | M20: 36 | N20: 54 | O20: 48 | P20: 40-60 | Q20: datasheet_local_pdf_verified | R20: Local PDF: SUN-_12-18_K-SG01LP1-EU-AM3-P_RU.pdf
A21: Deye | B21: Hybrid LV 3P | C21: SUN-5K-SG05LP3-EU-SM2 | D21: three-phase | E21: 5000 | F21: 10000 | G21: 800 | H21: 160 | I21: 200 | J21: 650 | K21: 2 | L21: 1+1 | M21: 20 | N21: 30 | O21: 48 | P21: 40-60 | Q21: datasheet_local_pdf_verified | R21: Local PDF: SUN-_3-12_K-SG05LP3-EU-SM2_RU.pdf
A22: Deye | B22: Hybrid LV 3P | C22: SUN-6K-SG05LP3-EU-SM2 | D22: three-phase | E22: 6000 | F22: 12000 | G22: 800 | H22: 160 | I22: 200 | J22: 650 | K22: 2 | L22: 1+1 | M22: 20 | N22: 30 | O22: 48 | P22: 40-60 | Q22: datasheet_local_pdf_verified | R22: Local PDF: SUN-_3-12_K-SG05LP3-EU-SM2_RU.pdf
A23: Deye | B23: Hybrid LV 3P | C23: SUN-8K-SG05LP3-EU-SM2 | D23: three-phase | E23: 8000 | F23: 16000 | G23: 800 | H23: 160 | I23: 200 | J23: 650 | K23: 2 | L23: 2+2 | M23: 26 | N23: 39 | O23: 48 | P23: 40-60 | Q23: datasheet_local_pdf_verified | R23: Local PDF: SUN-_3-12_K-SG05LP3-EU-SM2_RU.pdf
... A30: Deye | B30: Hybrid LV 3P | C30: SUN-20K-SG05LP3-EU-SM2 | D30: three-phase | E30: 20000 | F30: 40000 | G30: 800 | H30: 160 | I30: 160 | J30: 650 | K30: 2 | L30: 2+2 | M30: 36 | N30: 54 | O30: 48 | P30: 40-60 | Q30: datasheet_local_pdf_verified | R30: Local PDF: SUN-_14-20_K-SG05LP3-EU-SM2_RU.pdf
A31: Deye | B31: Hybrid HV 3P | C31: SUN-10K-SG01HP3-EU-AM2 | D31: three-phase | E31: 10000 | F31: 20000 | G31: 1000 | H31: 180 | I31: 150 | J31: 850 | K31: 2 | L31: 1+1 | M31: 20 | N31: 30 | P31: 160-700 | Q31: datasheet_local_pdf_verified | R31: Local PDF: SUN-_5-25_K-SG01HP3-EU-AM2_RU.pdf
A32: Deye | B32: Hybrid HV 3P | C32: SUN-12K-SG01HP3-EU-AM2 | D32: three-phase | E32: 12000 | F32: 24000 | G32: 1000 | H32: 180 | I32: 150 | J32: 850 | K32: 2 | L32: 1+1 | M32: 20 | N32: 30 | P32: 160-700 | Q32: datasheet_local_pdf_verified | R32: Local PDF: SUN-_5-25_K-SG01HP3-EU-AM2_RU.pdf
A33: Deye | B33: Hybrid HV 3P | C33: SUN-15K-SG01HP3-EU-AM2 | D33: three-phase | E33: 15000 | F33: 30000 | G33: 1000 | H33: 180 | I33: 150 | J33: 850 | K33: 2 | L33: 2+2 | M33: 26 | N33: 39 | P33: 160-700 | Q33: datasheet_local_pdf_verified | R33: Local PDF: SUN-_5-25_K-SG01HP3-EU-AM2_RU.pdf
A34: Deye | B34: Hybrid HV 3P | C34: SUN-20K-SG01HP3-EU-AM2 | D34: three-phase | E34: 20000 | F34: 40000 | G34: 1000 | H34: 180 | I34: 150 | J34: 850 | K34: 2 | L34: 2+2 | M34: 26 | N34: 39 | P34: 160-700 | Q34: datasheet_local_pdf_verified | R34: Local PDF: SUN-_5-25_K-SG01HP3-EU-AM2_RU.pdf
A35: Deye | B35: Hybrid HV 3P | C35: SUN-25K-SG01HP3-EU-AM2 | D35: three-phase | E35: 25000 | F35: 50000 | G35: 1000 | H35: 180 | I35: 150 | J35: 850 | K35: 2 | L35: 2+1 | M35: 26 | N35: 39 | P35: 160-700 | Q35: datasheet_local_pdf_verified | R35: Local PDF: SUN-_5-25_K-SG01HP3-EU-AM2_RU.pdf
A36: Deye | B36: Hybrid HV 3P | C36: SUN-30K-SG02HP3-EU-AM3 | D36: three-phase | E36: 30000 | F36: 60000 | G36: 1000 | H36: 180 | I36: 150 | J36: 850 | K36: 3 | L36: 2+2+2 | M36: 36 | N36: 54 | P36: 160-700 | Q36: datasheet_local_pdf_verified | R36: Local PDF: SUN-_25-30_K-SG02HP3-EU-AM3_RU.pdf
A37: Deye | B37: Hybrid HV 3P | C37: SUN-40K-SG01HP3-EU-BM4 | D37: three-phase | E37: 40000 | F37: 80000 | G37: 1000 | H37: 180 | I37: 150 | J37: 850 | K37: 3 | L37: 2+2+2 | M37: 36 | N37: 55 | P37: 160-800 | Q37: datasheet_local_pdf_verified | R37: Local PDF: SUN-_29.9-50_K-SG01HP3-EU-BM4_RU.pdf
A38: Deye | B38: Hybrid HV 3P | C38: SUN-50K-SG01HP3-EU-BM4 | D38: three-phase | E38: 50000 | F38: 100000 | G38: 1000 | H38: 180 | I38: 150 | J38: 850 | K38: 4 | L38: 2+2+2+2 | M38: 36 | N38: 55 | P38: 160-800 | Q38: datasheet_local_pdf_verified | R38: Local PDF: SUN-_29.9-50_K-SG01HP3-EU-BM4_RU.pdf
A39: Deye | B39: Hybrid HV 3P | C39: SUN-60K-SG02HP3-EU-EM6 | D39: three-phase | E39: 60000 | F39: 120000 | G39: 1000 | H39: 180 | I39: 150 | J39: 850 | K39: 6 | L39: 2+2+2+2+2+2 | M39: 36 | N39: 54 | P39: 160-1000 | Q39: datasheet_local_pdf_verified | R39: Local PDF: SUN-_60-80_K-SG02HP3-EU-EM6_RU.pdf
A40: Deye | B40: Hybrid HV 3P | C40: SUN-70K-SG02HP3-EU-EM6 | D40: three-phase | E40: 70000 | F40: 140000 | G40: 1000 | H40: 180 | I40: 150 | J40: 850 | K40: 6 | L40: 2+2+2+2+2+2 | M40: 36 | N40: 54 | P40: 160-1000 | Q40: datasheet_local_pdf_verified | R40: Local PDF: SUN-_60-80_K-SG02HP3-EU-EM6_RU.pdf
A41: Deye | B41: Hybrid HV 3P | C41: SUN-75K-SG02HP3-EU-EM6 | D41: three-phase | E41: 75000 | F41: 150000 | G41: 1000 | H41: 180 | I41: 150 | J41: 850 | K41: 6 | L41: 2+2+2+2+2+2 | M41: 36 | N41: 54 | P41: 160-1000 | Q41: datasheet_local_pdf_verified | R41: Local PDF: SUN-_60-80_K-SG02HP3-EU-EM6_RU.pdf
A42: Deye | B42: Hybrid HV 3P | C42: SUN-80K-SG02HP3-EU-EM6 | D42: three-phase | E42: 80000 | F42: 160000 | G42: 1000 | H42: 180 | I42: 150 | J42: 850 | K42: 6 | L42: 2+2+2+2+2+2 | M42: 36 | N42: 54 | P42: 160-1000 | Q42: datasheet_local_pdf_verified | R42: Local PDF: SUN-_60-80_K-SG02HP3-EU-EM6_RU.pdf
... A44: Deye | B44: Hybrid HV 3P | C44: SUN-125K-SG02HP3-EU-GM10 | D44: three-phase | E44: 125000 | F44: 250000 | G44: 1000 | H44: 180 | I44: 150 | J44: 850 | K44: 10 | L44: 2+2+2+2+2+2+2+2+2+2 | M44: 42 | N44: 63 | P44: 160-1000 | Q44: datasheet_local_pdf_verified | R44: Local PDF: SUN-_100-125_K-SG02HP3-EU-GM10_RU.pdf
A45: Deye | B45: Grid 1P | C45: SUN-1K-G04P1-EU-AM1 | D45: single-phase | E45: 1000 | Q45: model_only_needs_datasheet | R45: Model list provided by user; datasheet parameters pending.
A46: Deye | B46: Grid 1P | C46: SUN-1.5K-G04P1-EU-AM1 | D46: single-phase | E46: 1500 | Q46: model_only_needs_datasheet | R46: Model list provided by user; datasheet parameters pending.
A47: Deye | B47: Grid 1P | C47: SUN-2K-G04P1-EU-AM1 | D47: single-phase | E47: 2000 | Q47: model_only_needs_datasheet | R47: Model list provided by user; datasheet parameters pending.
...

Sheet Panels
A1: brand | B1: series | C1: model | D1: power_stc_w | E1: vmp_stc_v | F1: imp_stc_a | G1: voc_stc_v | H1: isc_stc_a | I1: temp_coeff_pmax_pct_c | J1: temp_coeff_voc_pct_c | K1: temp_coeff_isc_pct_c | L1: module_length_mm | M1: module_width_mm | N1: module_depth_mm | O1: data_status | P1: notes
A2: Astronergy | B2: ASTRO N5 | C2: CHSM54N-HC-430 | D2: 430 | O2: model_only_needs_datasheet | P2: Panel catalog model; datasheet parameters pending.
A3: Astronergy | B3: ASTRO N5 | C3: CHSM54N-HC-435 | D3: 435 | O3: model_only_needs_datasheet | P3: Panel catalog model; datasheet parameters pending.
A4: Astronergy | B4: ASTRO N5 | C4: CHSM54N-HC-440 | D4: 440 | O4: model_only_needs_datasheet | P4: Panel catalog model; datasheet parameters pending.
A5: Astronergy | B5: ASTRO N7 | C5: CHSM72N(DG)/F-BH-570 | D5: 570 | O5: model_only_needs_datasheet | P5: Panel catalog model; datasheet parameters pending.
A6: Astronergy | B6: ASTRO N7 | C6: CHSM72N(DG)/F-BH-575 | D6: 575 | O6: model_only_needs_datasheet | P6: Panel catalog model; datasheet parameters pending.
A7: Astronergy | B7: ASTRO N7 | C7: CHSM72N(DG)/F-BH-580 | D7: 580 | O7: model_only_needs_datasheet | P7: Panel catalog model; datasheet parameters pending.
A8: Astronergy | B8: ASTRO N7 | C8: CHSM66N(DG)/F-BH-615 | D8: 615 | O8: model_only_needs_datasheet | P8: Panel catalog model; datasheet parameters pending.
A9: Astronergy | B9: ASTRO N7 | C9: CHSM66N(DG)/F-BH-620 | D9: 620 | O9: model_only_needs_datasheet | P9: Panel catalog model; datasheet parameters pending.
A10: JA Solar | B10: DeepBlue 3.0 | C10: JAM54S30-410/MR | D10: 410 | O10: model_only_needs_datasheet | P10: Panel catalog model; datasheet parameters pending.
A11: JA Solar | B11: DeepBlue 3.0 | C11: JAM54S30-415/MR | D11: 415 | O11: model_only_needs_datasheet | P11: Panel catalog model; datasheet parameters pending.
A12: JA Solar | B12: DeepBlue 3.0 | C12: JAM54S30-420/MR | D12: 420 | O12: model_only_needs_datasheet | P12: Panel catalog model; datasheet parameters pending.
A13: JA Solar | B13: DeepBlue 3.0 Pro | C13: JAM54D40-440/LB | D13: 440 | O13: model_only_needs_datasheet | P13: Panel catalog model; datasheet parameters pending.
... A28: Jinko | B28: Tiger Neo N-type 66HL4M | C28: JKM620N-66HL4M-V | D28: 620 | O28: model_only_needs_datasheet | P28: Panel catalog model; datasheet parameters pending.
A29: Jinko | B29: Tiger Neo N-type 72HL4 | C29: JKM565N-72HL4-V | D29: 565 | E29: 43.28 | F29: 13.06 | G29: 51.7 | H29: 13.86 | I29: -0.29 | J29: -0.25 | K29: 0.045 | L29: 2278 | M29: 1134 | N29: 30 | O29: seed_verify_datasheet | P29: Starter record for string sizing tests.
A30: Jinko | B30: Tiger Neo N-type 72HL4 | C30: JKM570N-72HL4-V | D30: 570 | E30: 43.52 | F30: 13.1 | G30: 51.89 | H30: 13.89 | I30: -0.29 | J30: -0.25 | K30: 0.045 | L30: 2278 | M30: 1134 | N30: 30 | O30: seed_verify_datasheet | P30: Starter record for string sizing tests.
A31: Jinko | B31: Tiger Neo N-type 72HL4 | C31: JKM575N-72HL4-V | D31: 575 | E31: 43.76 | F31: 13.14 | G31: 52.08 | H31: 13.92 | I31: -0.29 | J31: -0.25 | K31: 0.045 | L31: 2278 | M31: 1134 | N31: 30 | O31: seed_verify_datasheet | P31: Starter record for string sizing tests.
A32: Jinko | B32: Tiger Neo N-type 72HL4 | C32: JKM580N-72HL4-V | D32: 580 | E32: 43.99 | F32: 13.19 | G32: 52.27 | H32: 13.96 | I32: -0.29 | J32: -0.25 | K32: 0.045 | L32: 2278 | M32: 1134 | N32: 30 | O32: seed_verify_datasheet | P32: Starter record for string sizing tests.
A33: Jinko | B33: Tiger Neo N-type 72HL4 | C33: JKM585N-72HL4-V | D33: 585 | E33: 44.23 | F33: 13.23 | G33: 52.46 | H33: 14 | I33: -0.29 | J33: -0.25 | K33: 0.045 | L33: 2278 | M33: 1134 | N33: 30 | O33: seed_verify_datasheet | P33: Starter record for string sizing tests.
A34: LONGi | B34: Hi-MO 6 Explorer | C34: LR5-54HTH-425M | D34: 425 | O34: model_only_needs_datasheet | P34: Panel catalog model; datasheet parameters pending.
A35: LONGi | B35: Hi-MO 6 Explorer | C35: LR5-54HTH-430M | D35: 430 | O35: model_only_needs_datasheet | P35: Panel catalog model; datasheet parameters pending.
A36: LONGi | B36: Hi-MO 6 Explorer | C36: LR5-54HTH-435M | D36: 435 | O36: model_only_needs_datasheet | P36: Panel catalog model; datasheet parameters pending.
A37: LONGi | B37: Hi-MO 7 | C37: LR5-72HGD-585M | D37: 585 | O37: model_only_needs_datasheet | P37: Panel catalog model; datasheet parameters pending.
A38: LONGi | B38: Hi-MO 7 | C38: LR5-72HGD-590M | D38: 590 | O38: model_only_needs_datasheet | P38: Panel catalog model; datasheet parameters pending.
A39: LONGi | B39: Hi-MO 7 | C39: LR5-72HGD-595M | D39: 595 | O39: model_only_needs_datasheet | P39: Panel catalog model; datasheet parameters pending.
A40: LONGi | B40: Hi-MO X6 | C40: LR5-54HTB-430M | D40: 430 | O40: model_only_needs_datasheet | P40: Panel catalog model; datasheet parameters pending.
A41: LONGi | B41: Hi-MO X6 | C41: LR5-54HTB-435M | D41: 435 | O41: model_only_needs_datasheet | P41: Panel catalog model; datasheet parameters pending.
A42: LONGi | B42: Hi-MO 6 | C42: LR5-72HTH-565M | D42: 565 | E42: 42.94 | F42: 13.16 | G42: 51.21 | H42: 14.01 | I42: -0.29 | J42: -0.23 | K42: 0.05 | L42: 2278 | M42: 1134 | N42: 35 | O42: seed_verify_datasheet | P42: Starter record for string sizing tests.
A43: LONGi | B43: Hi-MO 6 | C43: LR5-72HTH-570M | D43: 570 | E43: 43.13 | F43: 13.22 | G43: 51.4 | H43: 14.07 | I43: -0.29 | J43: -0.23 | K43: 0.05 | L43: 2278 | M43: 1134 | N43: 35 | O43: seed_verify_datasheet | P43: Starter record for string sizing tests.
A44: LONGi | B44: Hi-MO 6 | C44: LR5-72HTH-575M | D44: 575 | E44: 43.32 | F44: 13.28 | G44: 51.59 | H44: 14.14 | I44: -0.29 | J44: -0.23 | K44: 0.05 | L44: 2278 | M44: 1134 | N44: 35 | O44: seed_verify_datasheet | P44: Starter record for string sizing tests.
A45: LONGi | B45: Hi-MO 6 | C45: LR5-72HTH-580M | D45: 580 | E45: 43.51 | F45: 13.34 | G45: 51.78 | H45: 14.2 | I45: -0.29 | J45: -0.23 | K45: 0.05 | L45: 2278 | M45: 1134 | N45: 35 | O45: seed_verify_datasheet | P45: Starter record for string sizing tests.
A46: LONGi | B46: Hi-MO 6 | C46: LR5-72HTH-585M | D46: 585 | E46: 43.7 | F46: 13.39 | G46: 51.97 | H46: 14.26 | I46: -0.29 | J46: -0.23 | K46: 0.05 | L46: 2278 | M46: 1134 | N46: 35 | O46: seed_verify_datasheet | P46: Starter record for string sizing tests.
A47: SunPro | B47: SPDG N-type | C47: SPDG430-N108M10 | D47: 430 | O47: model_only_needs_datasheet | P47: Panel catalog model; datasheet parameters pending.
A48: SunPro | B48: SPDG N-type | C48: SPDG435-N108M10 | D48: 435 | O48: model_only_needs_datasheet | P48: Panel catalog model; datasheet parameters pending.
A49: SunPro | B49: SPDG N-type | C49: SPDG440-N108M10 | D49: 440 | O49: model_only_needs_datasheet | P49: Panel catalog model; datasheet parameters pending.
A50: SunPro | B50: SPDG N-type | C50: SPDG570-N144M10 | D50: 570 | O50: model_only_needs_datasheet | P50: Panel catalog model; datasheet parameters pending.
A51: SunPro | B51: SPDG N-type | C51: SPDG575-N144M10 | D51: 575 | O51: model_only_needs_datasheet | P51: Panel catalog model; datasheet parameters pending.
A52: SunPro | B52: SPDG N-type | C52: SPDG580-N144M10 | D52: 580 | O52: model_only_needs_datasheet | P52: Panel catalog model; datasheet parameters pending.
A53: SunPro | B53: SPDG N-type | C53: SPDG585-N144M10 | D53: 585 | O53: model_only_needs_datasheet | P53: Panel catalog model; datasheet parameters pending.
A54: Trina | B54: Vertex S+ | C54: TSM-NEG9R.25-430 | D54: 430 | O54: model_only_needs_datasheet | P54: Panel catalog model; datasheet parameters pending.
...

Sheet Batteries
A1: brand | B1: series | C1: model | D1: chemistry | E1: nominal_energy_kwh | F1: usable_energy_kwh | G1: nominal_voltage_v | H1: capacity_ah | I1: cycle_life_min | J1: cycle_life_max | K1: communication | L1: bms | M1: compatibility | N1: data_status | O1: notes
A2: Pylontech | B2: US Series | C2: US5000 | D2: LiFePO4 | E2: 4.8 | G2: 48 | I2: 6000 | J2: 8000 | K2: CAN/RS485 | L2: Integrated BMS | M2: Deye compatible | N2: seed_verify_datasheet | O2: User-listed premium battery; verify exact usable energy and protocol settings.
A3: Pylontech | B3: Force L2 | C3: Force L2 | D3: LiFePO4 | I3: 6000 | J3: 8000 | K3: CAN/RS485 | L3: Integrated BMS | M3: Deye compatible | N3: model_only_needs_datasheet | O3: User-listed premium low-voltage stack; datasheet parameters pending.
A4: Pylontech | B4: Force H2 | C4: Force H2 | D4: LiFePO4 | I4: 6000 | J4: 8000 | K4: CAN/RS485 | L4: Integrated BMS | M4: Deye compatible | N4: model_only_needs_datasheet | O4: User-listed premium high-voltage stack; datasheet parameters pending.
A5: Dyness | B5: BX Series | C5: BX51100 | D5: LiFePO4 | E5: 5.12 | G5: 51.2 | H5: 100 | K5: CAN/RS485 | L5: Integrated BMS | M5: Deye compatible | N5: seed_verify_datasheet | O5: User-listed value battery; verify exact cycle life and protocol settings.
A6: Dyness | B6: PowerRack | C6: PowerRack | D6: LiFePO4 | K6: CAN/RS485 | L6: Integrated BMS | M6: Deye compatible | N6: model_only_needs_datasheet | O6: User-listed rack battery series; datasheet parameters pending.
A7: Dyness | B7: Tower | C7: Tower | D7: LiFePO4 | K7: CAN/RS485 | L7: Integrated BMS | M7: Deye compatible | N7: model_only_needs_datasheet | O7: User-listed stack battery series; datasheet parameters pending.
A8: Deye ESS | B8: SE Series | C8: SE-G5.1 | D8: LiFePO4 | E8: 5.12 | G8: 51.2 | H8: 100 | K8: CAN/RS485 | L8: Deye BMS | M8: Deye native | N8: seed_verify_datasheet | O8: Deye ESS model; native protocol expected; verify datasheet.
A9: Deye ESS | B9: SE Series | C9: SE-F5 | D9: LiFePO4 | E9: 5.12 | G9: 51.2 | H9: 100 | K9: CAN/RS485 | L9: Deye BMS | M9: Deye native | N9: model_only_needs_datasheet | O9: Deye ESS model; datasheet parameters pending.
A10: Deye ESS | B10: RW Series | C10: RW-F16 | D10: LiFePO4 | E10: 16 | G10: 51.2 | K10: CAN/RS485 | L10: Deye BMS | M10: Deye native | N10: seed_verify_datasheet | O10: Deye ESS high-capacity model; verify exact energy and current limits.
A11: Gobel Power | B11: Rack/Wall | C11: Gobel Power 5.12kWh 51.2V 100Ah | D11: LiFePO4 | E11: 5.12 | G11: 51.2 | H11: 100 | K11: CAN/RS485 | L11: JK/PACE BMS | M11: Deye compatible | N11: model_only_needs_datasheet | O11: User-listed mid-segment supplier; often EVE Grade A+ cells.
A12: Gobel Power | B12: Rack/Wall | C12: Gobel Power 10.24kWh 51.2V 200Ah | D12: LiFePO4 | E12: 10.24 | G12: 51.2 | H12: 200 | K12: CAN/RS485 | L12: JK/PACE BMS | M12: Deye compatible | N12: model_only_needs_datasheet | O12: User-listed mid-segment supplier; datasheet parameters pending.
A13: GSL Energy | B13: Wall/Rack | C13: GSL 5.12kWh 51.2V 100Ah | D13: LiFePO4 | E13: 5.12 | G13: 51.2 | H13: 100 | K13: CAN/RS485 | L13: Integrated BMS | M13: Deye compatible | N13: model_only_needs_datasheet | O13: User-listed supplier; EVE/CATL cells reported by user.
A14: GSL Energy | B14: Wall/Rack | C14: GSL 10.24kWh 51.2V 200Ah | D14: LiFePO4 | E14: 10.24 | G14: 51.2 | H14: 200 | K14: CAN/RS485 | L14: Integrated BMS | M14: Deye compatible | N14: model_only_needs_datasheet | O14: User-listed supplier; datasheet parameters pending.
A15: Felicity ESS | B15: LPBA Series | C15: LPBA48100-OL | D15: LiFePO4 | E15: 5.12 | G15: 51.2 | H15: 100 | K15: CAN/RS485 | L15: Integrated BMS | M15: Deye compatible | N15: model_only_needs_datasheet | O15: Common Felicity low-voltage model candidate; datasheet parameters pending.
A16: Felicity ESS | B16: LPBF Series | C16: LPBF48100-M | D16: LiFePO4 | E16: 5.12 | G16: 51.2 | H16: 100 | K16: CAN/RS485 | L16: Integrated BMS | M16: Deye compatible | N16: model_only_needs_datasheet | O16: Common Felicity low-voltage model candidate; datasheet parameters pending.
A17: HinaESS | B17: Rack/Commercial | C17: HinaESS 5.12kWh 51.2V 100Ah | D17: LiFePO4 | E17: 5.12 | G17: 51.2 | H17: 100 | K17: CAN/RS485 | L17: Integrated BMS | M17: Deye compatible | N17: model_only_needs_datasheet | O17: User-listed commercial battery supplier; datasheet parameters pending.
A18: HinaESS | B18: Rack/Commercial | C18: HinaESS 10.24kWh 51.2V 200Ah | D18: LiFePO4 | E18: 10.24 | G18: 51.2 | H18: 200 | K18: CAN/RS485 | L18: Integrated BMS | M18: Deye compatible | N18: model_only_needs_datasheet | O18: User-listed commercial battery supplier; datasheet parameters pending.
A19: Basen Green | B19: Rack/Wall | C19: Basen Green 5.12kWh 51.2V 100Ah | D19: LiFePO4 | E19: 5.12 | G19: 51.2 | H19: 100 | K19: CAN/RS485 | L19: Integrated BMS | M19: Deye compatible | N19: model_only_needs_datasheet | O19: OEM battery candidate; datasheet parameters pending.
A20: Basen Green | B20: Rack/Wall | C20: Basen Green 10.24kWh 51.2V 200Ah | D20: LiFePO4 | E20: 10.24 | G20: 51.2 | H20: 200 | K20: CAN/RS485 | L20: Integrated BMS | M20: Deye compatible | N20: model_only_needs_datasheet | O20: OEM battery candidate; datasheet parameters pending.
A21: HTE | B21: Rack/Wall | C21: HTE 5.12kWh 51.2V 100Ah | D21: LiFePO4 | E21: 5.12 | G21: 51.2 | H21: 100 | K21: CAN/RS485 | L21: Integrated BMS | M21: Deye compatible | N21: model_only_needs_datasheet | O21: OEM battery candidate; datasheet parameters pending.
A22: SRNE ESS | B22: Rack/Wall | C22: SRNE ESS 5.12kWh 51.2V 100Ah | D22: LiFePO4 | E22: 5.12 | G22: 51.2 | H22: 100 | K22: CAN/RS485 | L22: Integrated BMS | M22: Deye compatible | N22: model_only_needs_datasheet | O22: OEM battery candidate; datasheet parameters pending.
... A25: EVE Energy ESS | B25: Rack/Wall | C25: EVE Energy ESS 5.12kWh 51.2V 100Ah | D25: LiFePO4 | E25: 5.12 | G25: 51.2 | H25: 100 | K25: CAN/RS485 | L25: Integrated BMS | M25: Deye compatible | N25: model_only_needs_datasheet | O25: OEM battery candidate; datasheet parameters pending.

Sheet Mounting
A1: Mounting quantity | B1: Value | C1: Unit | D1: Formula / meaning
A2: Roof type | B2: =Inputs!B11 | D2: From Inputs
A3: Total panels | B3: =Inputs!B12 | C3: pcs | D3: From Inputs
A4: Panels per row | B4: =Inputs!B13 | C4: pcs | D4: From Inputs
A5: Rows | B5: =ROUNDUP(B3/B4,0) | C5: rows | D5: Calculated from total panels and panels per row
A6: Rail lines | B6: =B5*2 | C6: pcs | D6: Two rail lines per row
A7: Estimated rail length | B7: =B3*Inputs!B15*2 | C7: m | D7: Total panels x rail length per panel x 2
A8: Rail joints | B8: =MAX(0,ROUNDUP(B7/Inputs!B14,0)-B6) | C8: pcs | D8: Estimated from rail length and stock length
A9: Reserve | B9: =Inputs!B16 | C9: % | D9: Extra quantity reserve
A10: Component | B10: Quantity | C10: Unit | D10: Notes
A11: Roof hooks / seam clamps / ground posts | B11: =ROUNDUP((SUMIFS(MountingRules!D:D,MountingRules!A:A,B2,MountingRules!B:B,"Roof hook")+SUMIFS(MountingRules!D:D,MountingRules!A:A,B2,MountingRules!B:B,"Mini rail clamp")+SUMIFS(MountingRules!E:E,MountingRules!A:A,B2,MountingRules!B:B,"Ground post"))*B3*(1+B9/100),0) | C11: pcs | D11: Hooks, seam clamps, or ground posts depending on installation type
A12: Mini-rails | B12: =ROUNDUP(SUMIFS(MountingRules!D:D,MountingRules!A:A,B2,MountingRules!B:B,"*Mini rail*")*B3*(1+B9/100),0) | C12: pcs | D12: Used for mini-rail roof systems
A13: Rails | B13: =ROUNDUP(B7/Inputs!B12*(1+B9/100),0) | C13: pcs | D13: Rail stock pieces
A14: Rail connectors | B14: =ROUNDUP(B8*2*(1+B9/100),0) | C14: pcs | D14: Usually two per rail joint
A15: End clamps | B15: =ROUNDUP(B5*4*(1+B9/100),0) | C15: pcs | D15: Four per row
A16: Middle clamps | B16: =ROUNDUP(MAX(0,(B3-B5)*2)*(1+B9/100),0) | C16: pcs | D16: Two per gap between panels in a row
A17: Bolt sets | B17: =ROUNDUP((SUMIFS(MountingRules!D:D,MountingRules!A:A,B2,MountingRules!B:B,"Bolt set")+SUMIFS(MountingRules!D:D,MountingRules!A:A,B2,MountingRules!B:B,"Self-drilling screw set"))*B3*(1+B9/100),0) | C17: pcs | D17: Fastener allowance
A18: Grounding clips | B18: =ROUNDUP(B3*(1+B9/100),0) | C18: pcs | D18: One per panel starter assumption
A19: Cable clips | B19: =ROUNDUP(B3*2*(1+B9/100),0) | C19: pcs | D19: Two per panel starter assumption

Sheet Equipment
A1: Category | B1: Item | C1: Quantity | D1: Unit | E1: Notes
A2: Inverter | B2: =Inputs!B3 | C2: 1 | D2: pcs | E2: Selected inverter
A3: Solar panels | B3: =Inputs!B4 | C3: =Inputs!B12 | D3: pcs | E3: Total panel quantity
A4: Battery | B4: =Inputs!B9 | C4: =Inputs!B10 | D4: pcs | E4: Selected battery quantity
A5: Battery energy | B5: =Inputs!B9&" total nominal energy" | C5: =Results!B29 | D5: kWh | E5: Total nominal battery energy
A6: Mounting | B6: Roof hooks / seam clamps / ground posts | C6: =Mounting!B11 | D6: pcs | E6: From Mounting sheet
A7: Mounting | B7: Mini-rails | C7: =Mounting!B12 | D7: pcs | E7: From Mounting sheet
A8: Mounting | B8: Rails | C8: =Mounting!B13 | D8: pcs | E8: From Mounting sheet
A9: Mounting | B9: Rail connectors | C9: =Mounting!B14 | D9: pcs | E9: From Mounting sheet
A10: Mounting | B10: End clamps | C10: =Mounting!B15 | D10: pcs | E10: From Mounting sheet
A11: Mounting | B11: Middle clamps | C11: =Mounting!B16 | D11: pcs | E11: From Mounting sheet
A12: Mounting | B12: Bolt sets | C12: =Mounting!B17 | D12: pcs | E12: From Mounting sheet
A13: Mounting | B13: Grounding clips | C13: =Mounting!B18 | D13: pcs | E13: From Mounting sheet
A14: Mounting | B14: Cable clips | C14: =Mounting!B19 | D14: pcs | E14: From Mounting sheet
A15: Protection | B15: PV cable red | C15: =CableProtection!B2 | D15: m | E15: From CableProtection sheet
A16: Protection | B16: PV cable black | C16: =CableProtection!B3 | D16: m | E16: From CableProtection sheet
A17: Protection | B17: PE cable | C17: =CableProtection!B4 | D17: m | E17: From CableProtection sheet
A18: Protection | B18: DC string fuses | C18: =CableProtection!B5 | D18: pcs | E18: From CableProtection sheet
A19: Protection | B19: DC isolator | C19: =CableProtection!B6 | D19: pcs | E19: From CableProtection sheet
A20: Protection | B20: DC SPD Type 2 | C20: =CableProtection!B7 | D20: pcs | E20: From CableProtection sheet
A21: Protection | B21: AC breaker | C21: =CableProtection!B8 | D21: pcs | E21: From CableProtection sheet
A22: Protection | B22: AC SPD Type 2 | C22: =CableProtection!B9 | D22: pcs | E22: From CableProtection sheet
A23: Protection | B23: AC cable | C23: =CableProtection!B10 | D23: m | E23: From CableProtection sheet
A24: Protection | B24: Battery DC cable pair | C24: =CableProtection!B11 | D24: pair | E24: From CableProtection sheet
A25: Protection | B25: Battery fuse or breaker | C25: =CableProtection!B12 | D25: pcs | E25: From CableProtection sheet
A26: Sizing | B26: Recommended DC cable section | C26: =CableProtection!B15 | D26: mm2 | E26: Starter sizing; verify installation method
A27: Sizing | B27: DC voltage drop | C27: =CableProtection!B16 | D27: % | E27: Starter voltage-drop estimate
A28: Sizing | B28: Recommended AC cable section | C28: =CableProtection!B19 | D28: mm2 | E28: Starter sizing; verify installation method
A29: Sizing | B29: AC voltage drop | C29: =CableProtection!B20 | D29: % | E29: Starter voltage-drop estimate
A30: Sizing | B30: Recommended battery cable section | C30: =CableProtection!B24 | D30: mm2 | E30: Starter sizing; verify installation method
A31: Sizing | B31: Estimated battery current | C31: =CableProtection!B23 | D31: A | E31: Inverter power / battery voltage
A32: Sizing | B32: Cable derating factor | C32: =CableProtection!B30 | D32: factor | E32: Grouping x ambient derating
A33: Protection | B33: Recommended SPD type | C33: =CableProtection!B28 | E33: Starter selection; verify local standards
A34: Protection | B34: AC earthing system | C34: =CableProtection!B29 | E34: Selected earthing checklist
A35: Documentation | B35: Datasheet verification | C35: 1 | D35: task | E35: Required before commercial use

Sheet CableProtection
A1: Cable / Protection item | B1: Quantity | C1: Unit | D1: Formula / meaning
A2: PV cable red | B2: =Inputs!B17 | C2: m | D2: DC cable route length
A3: PV cable black | B3: =Inputs!B17 | C3: m | D3: DC cable route length
A4: PE cable | B4: =Inputs!B19 | C4: m | D4: Grounding route length
A5: DC string fuses | B5: =IF(Inputs!B8>1,Inputs!B8*2,0) | C5: pcs | D5: Used when strings per MPPT > 1
A6: DC isolator | B6: =1 | C6: pcs | D6: Starter quantity
A7: DC SPD Type 2 | B7: =1 | C7: pcs | D7: Starter quantity
A8: AC breaker | B8: =1 | C8: pcs | D8: Starter quantity; rating must be selected
A9: AC SPD Type 2 | B9: =1 | C9: pcs | D9: Starter quantity
A10: AC cable | B10: =Inputs!B18 | C10: m | D10: AC cable route length
A11: Battery DC cable pair | B11: =1 | C11: pair | D11: Starter quantity
A12: Battery fuse or breaker | B12: =1 | C12: pcs | D12: Starter quantity; rating must be selected
A13: Protection design status | B13: ="VERIFY" | D13: VERIFY until ratings and cable sections are selected
A15: Sizing result | B15: =MAX(4,LOOKUP((Results!B12*Inputs!B8)/B30,CableSizing!B:B,CableSizing!A:A)) | C15: Unit | D15: Formula / meaning
A16: Recommended DC cable section | B16: =ROUND(2*Inputs!B17*Results!B12*Inputs!B8*0.0175/(B15*Results!B17)*100,2) | C16: mm2 | D16: Based on PV operating current
A17: DC voltage drop | B17: =LOOKUP(INDEX(Panels!H:H,MATCH(Inputs!B4,Panels!C:C,0))*1.25,{0,16,20,25,32},{16,20,25,32,40}) | C17: % | D17: 2 x length x current x copper resistance / section / voltage
A18: Suggested DC fuse rating | B18: =ROUND(INDEX(Inverters!E:E,MATCH(Inputs!B3,Inverters!C:C,0))/IF(INDEX(Inverters!D:D,MATCH(Inputs!B3,Inverters!C:C,0))="three-phase",692.8,230),1) | C18: A | D18: Based on string short-circuit current
A19: Estimated AC current | B19: =MAX(2.5,LOOKUP(B18/B30,CableSizing!B:B,CableSizing!A:A)) | C19: A | D19: Based on inverter AC power and phase
A20: Recommended AC cable section | B20: =ROUND(IF(INDEX(Inverters!D:D,MATCH(Inputs!B3,Inverters!C:C,0))="three-phase",1.732*Inputs!B18*B18*0.0175/(B19*400)*100,2*Inputs!B18*B18*0.0175/(B19*230)*100),2) | C20: mm2 | D20: Based on estimated AC current
A21: AC voltage drop | B21: =LOOKUP(B18*1.25,{0,16,20,25,32,40,50,63,80,100,125,160},{16,20,25,32,40,50,63,80,100,125,160,200}) | C21: % | D21: Starter single/three-phase voltage-drop estimate
A22: Suggested AC breaker rating | C22: A | D22: Next common rating above AC current
A23: Estimated battery current | B23: =ROUND(INDEX(Inverters!E:E,MATCH(Inputs!B3,Inverters!C:C,0))/INDEX(Batteries!G:G,MATCH(Inputs!B9,Batteries!C:C,0)),1) | C23: A | D23: AC power / battery nominal voltage
A24: Recommended battery cable section | B24: =MAX(16,LOOKUP(B23/B30,CableSizing!B:B,CableSizing!A:A)) | C24: mm2 | D24: Based on estimated battery current
A25: Suggested battery breaker rating | B25: =LOOKUP(B23*1.25,{0,63,80,100,125,160,200,250},{63,80,100,125,160,200,250,315}) | C25: A | D25: Next common rating above battery current
A26: Sizing status | B26: ="VERIFY" | D26: VERIFY until local standards and datasheets are checked
A28: Advanced protection result | B28: =IF(Inputs!B23="External LPS","Type 1+2 DC/AC SPD",IF(Inputs!B23="Overhead supply","Type 1+2 AC SPD + Type 2 DC SPD",IF(Inputs!B23="Long outdoor DC route","Type 2 DC SPD near inverter and array","Type 2 DC/AC SPD"))) | C28: Unit | D28: Formula / meaning
A29: Recommended SPD type | B29: =Inputs!B24 | D29: Based on selected lightning protection condition
A30: AC earthing system | B30: =MAX(0.1,Inputs!B21*Inputs!B22) | D30: Selected earthing system checklist
A31: Combined cable derating factor | B31: =INDEX(CableSizing!B:B,MATCH(B15,CableSizing!A:A,0))*B30 | C31: factor | D31: Grouping derating x ambient derating
A32: Derated DC cable ampacity | B32: ="VERIFY" | C32: A | D32: Selected DC cable ampacity after derating
A33: Advanced protection status | D33: VERIFY until local standards are checked

Sheet BulkCompatibility
A1: Scenario | B1: Inverter | C1: Panel | D1: Battery | E1: Panels/string | F1: Strings/MPPT | G1: Cold string Voc | H1: Hot string Vmp | I1: PV voltage | J1: PV current | K1: Battery | L1: Overall | M1: Notes
A2: Residential 5kW Deye | B2: SUN-5K-SG03LP1-EU | C2: JKM575N-72HL4-V | D2: US5000 | E2: 8 | F2: 1 | G2: =ROUND(INDEX(Panels!G:G,MATCH(C2,Panels!C:C,0))*(1+(INDEX(Panels!J:J,MATCH(C2,Panels!C:C,0))/100)*(Inputs!B5-25))*E2,1) | H2: =ROUND(INDEX(Panels!E:E,MATCH(C2,Panels!C:C,0))*(1+(INDEX(Panels!J:J,MATCH(C2,Panels!C:C,0))/100)*(Inputs!B6-25))*E2,1) | I2: =IF(OR(INDEX(Inverters!Q:Q,MATCH(B2,Inverters!C:C,0))="model_only_needs_datasheet",INDEX(Panels!O:O,MATCH(C2,Panels!C:C,0))="model_only_needs_datasheet"),"VERIFY",IF(AND(G2<INDEX(Inverters!G:G,MATCH(B2,Inverters!C:C,0)),H2>=INDEX(Inverters!I:I,MATCH(B2,Inverters!C:C,0)),H2<=INDEX(Inverters!J:J,MATCH(B2,Inverters!C:C,0))),"PASS","FAIL")) | J2: =IF(OR(INDEX(Inverters!Q:Q,MATCH(B2,Inverters!C:C,0))="model_only_needs_datasheet",INDEX(Panels!O:O,MATCH(C2,Panels!C:C,0))="model_only_needs_datasheet"),"VERIFY",IF(INDEX(Panels!F:F,MATCH(C2,Panels!C:C,0))*F2<=INDEX(Inverters!M:M,MATCH(B2,Inverters!C:C,0)),"PASS","FAIL")) | K2: =IF(ISNUMBER(SEARCH("Deye",INDEX(Batteries!M:M,MATCH(D2,Batteries!C:C,0)))),"PASS","VERIFY") | L2: =IF(OR(I2="FAIL",J2="FAIL"),"FAIL",IF(OR(I2="VERIFY",J2="VERIFY",K2="VERIFY",INDEX(Inverters!Q:Q,MATCH(B2,Inverters!C:C,0))="model_only_needs_datasheet",INDEX(Panels!O:O,MATCH(C2,Panels!C:C,0))="model_only_needs_datasheet",INDEX(Batteries!N:N,MATCH(D2,Batteries!C:C,0))="model_only_needs_datasheet"),"VERIFY","PASS")) | M2: Starter Deye LV scenario.
A3: Residential 8kW Deye | B3: SUN-8K-SG01LP1-EU | C3: JKM575N-72HL4-V | D3: US5000 | E3: 8 | F3: 2 | G3: =ROUND(INDEX(Panels!G:G,MATCH(C3,Panels!C:C,0))*(1+(INDEX(Panels!J:J,MATCH(C3,Panels!C:C,0))/100)*(Inputs!B5-25))*E3,1) | H3: =ROUND(INDEX(Panels!E:E,MATCH(C3,Panels!C:C,0))*(1+(INDEX(Panels!J:J,MATCH(C3,Panels!C:C,0))/100)*(Inputs!B6-25))*E3,1) | I3: =IF(OR(INDEX(Inverters!Q:Q,MATCH(B3,Inverters!C:C,0))="model_only_needs_datasheet",INDEX(Panels!O:O,MATCH(C3,Panels!C:C,0))="model_only_needs_datasheet"),"VERIFY",IF(AND(G3<INDEX(Inverters!G:G,MATCH(B3,Inverters!C:C,0)),H3>=INDEX(Inverters!I:I,MATCH(B3,Inverters!C:C,0)),H3<=INDEX(Inverters!J:J,MATCH(B3,Inverters!C:C,0))),"PASS","FAIL")) | J3: =IF(OR(INDEX(Inverters!Q:Q,MATCH(B3,Inverters!C:C,0))="model_only_needs_datasheet",INDEX(Panels!O:O,MATCH(C3,Panels!C:C,0))="model_only_needs_datasheet"),"VERIFY",IF(INDEX(Panels!F:F,MATCH(C3,Panels!C:C,0))*F3<=INDEX(Inverters!M:M,MATCH(B3,Inverters!C:C,0)),"PASS","FAIL")) | K3: =IF(ISNUMBER(SEARCH("Deye",INDEX(Batteries!M:M,MATCH(D3,Batteries!C:C,0)))),"PASS","VERIFY") | L3: =IF(OR(I3="FAIL",J3="FAIL"),"FAIL",IF(OR(I3="VERIFY",J3="VERIFY",K3="VERIFY",INDEX(Inverters!Q:Q,MATCH(B3,Inverters!C:C,0))="model_only_needs_datasheet",INDEX(Panels!O:O,MATCH(C3,Panels!C:C,0))="model_only_needs_datasheet",INDEX(Batteries!N:N,MATCH(D3,Batteries!C:C,0))="model_only_needs_datasheet"),"VERIFY","PASS")) | M3: Starter two-string Deye LV scenario.
A4: Residential 6kW Deye | B4: SUN-6K-SG03LP1-EU | C4: LR5-72HTH-580M | D4: BX51100 | E4: 8 | F4: 1 | G4: =ROUND(INDEX(Panels!G:G,MATCH(C4,Panels!C:C,0))*(1+(INDEX(Panels!J:J,MATCH(C4,Panels!C:C,0))/100)*(Inputs!B5-25))*E4,1) | H4: =ROUND(INDEX(Panels!E:E,MATCH(C4,Panels!C:C,0))*(1+(INDEX(Panels!J:J,MATCH(C4,Panels!C:C,0))/100)*(Inputs!B6-25))*E4,1) | I4: =IF(OR(INDEX(Inverters!Q:Q,MATCH(B4,Inverters!C:C,0))="model_only_needs_datasheet",INDEX(Panels!O:O,MATCH(C4,Panels!C:C,0))="model_only_needs_datasheet"),"VERIFY",IF(AND(G4<INDEX(Inverters!G:G,MATCH(B4,Inverters!C:C,0)),H4>=INDEX(Inverters!I:I,MATCH(B4,Inverters!C:C,0)),H4<=INDEX(Inverters!J:J,MATCH(B4,Inverters!C:C,0))),"PASS","FAIL")) | J4: =IF(OR(INDEX(Inverters!Q:Q,MATCH(B4,Inverters!C:C,0))="model_only_needs_datasheet",INDEX(Panels!O:O,MATCH(C4,Panels!C:C,0))="model_only_needs_datasheet"),"VERIFY",IF(INDEX(Panels!F:F,MATCH(C4,Panels!C:C,0))*F4<=INDEX(Inverters!M:M,MATCH(B4,Inverters!C:C,0)),"PASS","FAIL")) | K4: =IF(ISNUMBER(SEARCH("Deye",INDEX(Batteries!M:M,MATCH(D4,Batteries!C:C,0)))),"PASS","VERIFY") | L4: =IF(OR(I4="FAIL",J4="FAIL"),"FAIL",IF(OR(I4="VERIFY",J4="VERIFY",K4="VERIFY",INDEX(Inverters!Q:Q,MATCH(B4,Inverters!C:C,0))="model_only_needs_datasheet",INDEX(Panels!O:O,MATCH(C4,Panels!C:C,0))="model_only_needs_datasheet",INDEX(Batteries!N:N,MATCH(D4,Batteries!C:C,0))="model_only_needs_datasheet"),"VERIFY","PASS")) | M4: Starter LONGi plus Dyness scenario.
A5: Commercial 10kW Deye | B5: SUN-10K-SG02LP1-EU-AM3-P | C5: TSM-NEG18R.28-500 | D5: SE-G5.1 | E5: 8 | F5: 1 | G5: =ROUND(INDEX(Panels!G:G,MATCH(C5,Panels!C:C,0))*(1+(INDEX(Panels!J:J,MATCH(C5,Panels!C:C,0))/100)*(Inputs!B5-25))*E5,1) | H5: =ROUND(INDEX(Panels!E:E,MATCH(C5,Panels!C:C,0))*(1+(INDEX(Panels!J:J,MATCH(C5,Panels!C:C,0))/100)*(Inputs!B6-25))*E5,1) | I5: =IF(OR(INDEX(Inverters!Q:Q,MATCH(B5,Inverters!C:C,0))="model_only_needs_datasheet",INDEX(Panels!O:O,MATCH(C5,Panels!C:C,0))="model_only_needs_datasheet"),"VERIFY",IF(AND(G5<INDEX(Inverters!G:G,MATCH(B5,Inverters!C:C,0)),H5>=INDEX(Inverters!I:I,MATCH(B5,Inverters!C:C,0)),H5<=INDEX(Inverters!J:J,MATCH(B5,Inverters!C:C,0))),"PASS","FAIL")) | J5: =IF(OR(INDEX(Inverters!Q:Q,MATCH(B5,Inverters!C:C,0))="model_only_needs_datasheet",INDEX(Panels!O:O,MATCH(C5,Panels!C:C,0))="model_only_needs_datasheet"),"VERIFY",IF(INDEX(Panels!F:F,MATCH(C5,Panels!C:C,0))*F5<=INDEX(Inverters!M:M,MATCH(B5,Inverters!C:C,0)),"PASS","FAIL")) | K5: =IF(ISNUMBER(SEARCH("Deye",INDEX(Batteries!M:M,MATCH(D5,Batteries!C:C,0)))),"PASS","VERIFY") | L5: =IF(OR(I5="FAIL",J5="FAIL"),"FAIL",IF(OR(I5="VERIFY",J5="VERIFY",K5="VERIFY",INDEX(Inverters!Q:Q,MATCH(B5,Inverters!C:C,0))="model_only_needs_datasheet",INDEX(Panels!O:O,MATCH(C5,Panels!C:C,0))="model_only_needs_datasheet",INDEX(Batteries!N:N,MATCH(D5,Batteries!C:C,0))="model_only_needs_datasheet"),"VERIFY","PASS")) | M5: Model-only scenario; datasheet values pending.
A6: Hybrid 12kW Deye | B6: SUN-12K-SG02LP1-EU-AM3-P | C6: JAM54D40-440/LB | D6: SE-G5.1 | E6: 8 | F6: 1 | G6: =ROUND(INDEX(Panels!G:G,MATCH(C6,Panels!C:C,0))*(1+(INDEX(Panels!J:J,MATCH(C6,Panels!C:C,0))/100)*(Inputs!B5-25))*E6,1) | H6: =ROUND(INDEX(Panels!E:E,MATCH(C6,Panels!C:C,0))*(1+(INDEX(Panels!J:J,MATCH(C6,Panels!C:C,0))/100)*(Inputs!B6-25))*E6,1) | I6: =IF(OR(INDEX(Inverters!Q:Q,MATCH(B6,Inverters!C:C,0))="model_only_needs_datasheet",INDEX(Panels!O:O,MATCH(C6,Panels!C:C,0))="model_only_needs_datasheet"),"VERIFY",IF(AND(G6<INDEX(Inverters!G:G,MATCH(B6,Inverters!C:C,0)),H6>=INDEX(Inverters!I:I,MATCH(B6,Inverters!C:C,0)),H6<=INDEX(Inverters!J:J,MATCH(B6,Inverters!C:C,0))),"PASS","FAIL")) | J6: =IF(OR(INDEX(Inverters!Q:Q,MATCH(B6,Inverters!C:C,0))="model_only_needs_datasheet",INDEX(Panels!O:O,MATCH(C6,Panels!C:C,0))="model_only_needs_datasheet"),"VERIFY",IF(INDEX(Panels!F:F,MATCH(C6,Panels!C:C,0))*F6<=INDEX(Inverters!M:M,MATCH(B6,Inverters!C:C,0)),"PASS","FAIL")) | K6: =IF(ISNUMBER(SEARCH("Deye",INDEX(Batteries!M:M,MATCH(D6,Batteries!C:C,0)))),"PASS","VERIFY") | L6: =IF(OR(I6="FAIL",J6="FAIL"),"FAIL",IF(OR(I6="VERIFY",J6="VERIFY",K6="VERIFY",INDEX(Inverters!Q:Q,MATCH(B6,Inverters!C:C,0))="model_only_needs_datasheet",INDEX(Panels!O:O,MATCH(C6,Panels!C:C,0))="model_only_needs_datasheet",INDEX(Batteries!N:N,MATCH(D6,Batteries!C:C,0))="model_only_needs_datasheet"),"VERIFY","PASS")) | M6: Model-only scenario; datasheet values pending.
A7: Growatt hybrid | B7: SPH 10000TL3 BH-UP | C7: JKM575N-72HL4-V | D7: US5000 | E7: 8 | F7: 1 | G7: =ROUND(INDEX(Panels!G:G,MATCH(C7,Panels!C:C,0))*(1+(INDEX(Panels!J:J,MATCH(C7,Panels!C:C,0))/100)*(Inputs!B5-25))*E7,1) | H7: =ROUND(INDEX(Panels!E:E,MATCH(C7,Panels!C:C,0))*(1+(INDEX(Panels!J:J,MATCH(C7,Panels!C:C,0))/100)*(Inputs!B6-25))*E7,1) | I7: =IF(OR(INDEX(Inverters!Q:Q,MATCH(B7,Inverters!C:C,0))="model_only_needs_datasheet",INDEX(Panels!O:O,MATCH(C7,Panels!C:C,0))="model_only_needs_datasheet"),"VERIFY",IF(AND(G7<INDEX(Inverters!G:G,MATCH(B7,Inverters!C:C,0)),H7>=INDEX(Inverters!I:I,MATCH(B7,Inverters!C:C,0)),H7<=INDEX(Inverters!J:J,MATCH(B7,Inverters!C:C,0))),"PASS","FAIL")) | J7: =IF(OR(INDEX(Inverters!Q:Q,MATCH(B7,Inverters!C:C,0))="model_only_needs_datasheet",INDEX(Panels!O:O,MATCH(C7,Panels!C:C,0))="model_only_needs_datasheet"),"VERIFY",IF(INDEX(Panels!F:F,MATCH(C7,Panels!C:C,0))*F7<=INDEX(Inverters!M:M,MATCH(B7,Inverters!C:C,0)),"PASS","FAIL")) | K7: =IF(ISNUMBER(SEARCH("Deye",INDEX(Batteries!M:M,MATCH(D7,Batteries!C:C,0)))),"PASS","VERIFY") | L7: =IF(OR(I7="FAIL",J7="FAIL"),"FAIL",IF(OR(I7="VERIFY",J7="VERIFY",K7="VERIFY",INDEX(Inverters!Q:Q,MATCH(B7,Inverters!C:C,0))="model_only_needs_datasheet",INDEX(Panels!O:O,MATCH(C7,Panels!C:C,0))="model_only_needs_datasheet",INDEX(Batteries!N:N,MATCH(D7,Batteries!C:C,0))="model_only_needs_datasheet"),"VERIFY","PASS")) | M7: Needs datasheet verification for exact Growatt electrical limits.
A8: Solis hybrid | B8: S6-EH3P10K-H-EU | C8: JKM575N-72HL4-V | D8: BX51100 | E8: 8 | F8: 1 | G8: =ROUND(INDEX(Panels!G:G,MATCH(C8,Panels!C:C,0))*(1+(INDEX(Panels!J:J,MATCH(C8,Panels!C:C,0))/100)*(Inputs!B5-25))*E8,1) | H8: =ROUND(INDEX(Panels!E:E,MATCH(C8,Panels!C:C,0))*(1+(INDEX(Panels!J:J,MATCH(C8,Panels!C:C,0))/100)*(Inputs!B6-25))*E8,1) | I8: =IF(OR(INDEX(Inverters!Q:Q,MATCH(B8,Inverters!C:C,0))="model_only_needs_datasheet",INDEX(Panels!O:O,MATCH(C8,Panels!C:C,0))="model_only_needs_datasheet"),"VERIFY",IF(AND(G8<INDEX(Inverters!G:G,MATCH(B8,Inverters!C:C,0)),H8>=INDEX(Inverters!I:I,MATCH(B8,Inverters!C:C,0)),H8<=INDEX(Inverters!J:J,MATCH(B8,Inverters!C:C,0))),"PASS","FAIL")) | J8: =IF(OR(INDEX(Inverters!Q:Q,MATCH(B8,Inverters!C:C,0))="model_only_needs_datasheet",INDEX(Panels!O:O,MATCH(C8,Panels!C:C,0))="model_only_needs_datasheet"),"VERIFY",IF(INDEX(Panels!F:F,MATCH(C8,Panels!C:C,0))*F8<=INDEX(Inverters!M:M,MATCH(B8,Inverters!C:C,0)),"PASS","FAIL")) | K8: =IF(ISNUMBER(SEARCH("Deye",INDEX(Batteries!M:M,MATCH(D8,Batteries!C:C,0)))),"PASS","VERIFY") | L8: =IF(OR(I8="FAIL",J8="FAIL"),"FAIL",IF(OR(I8="VERIFY",J8="VERIFY",K8="VERIFY",INDEX(Inverters!Q:Q,MATCH(B8,Inverters!C:C,0))="model_only_needs_datasheet",INDEX(Panels!O:O,MATCH(C8,Panels!C:C,0))="model_only_needs_datasheet",INDEX(Batteries!N:N,MATCH(D8,Batteries!C:C,0))="model_only_needs_datasheet"),"VERIFY","PASS")) | M8: Needs datasheet verification for exact Solis electrical limits.
A9: MUST hybrid | B9: PV1800 PRO-5.2KW-48V | C9: JKM575N-72HL4-V | D9: US5000 | E9: 4 | F9: 1 | G9: =ROUND(INDEX(Panels!G:G,MATCH(C9,Panels!C:C,0))*(1+(INDEX(Panels!J:J,MATCH(C9,Panels!C:C,0))/100)*(Inputs!B5-25))*E9,1) | H9: =ROUND(INDEX(Panels!E:E,MATCH(C9,Panels!C:C,0))*(1+(INDEX(Panels!J:J,MATCH(C9,Panels!C:C,0))/100)*(Inputs!B6-25))*E9,1) | I9: =IF(OR(INDEX(Inverters!Q:Q,MATCH(B9,Inverters!C:C,0))="model_only_needs_datasheet",INDEX(Panels!O:O,MATCH(C9,Panels!C:C,0))="model_only_needs_datasheet"),"VERIFY",IF(AND(G9<INDEX(Inverters!G:G,MATCH(B9,Inverters!C:C,0)),H9>=INDEX(Inverters!I:I,MATCH(B9,Inverters!C:C,0)),H9<=INDEX(Inverters!J:J,MATCH(B9,Inverters!C:C,0))),"PASS","FAIL")) | J9: =IF(OR(INDEX(Inverters!Q:Q,MATCH(B9,Inverters!C:C,0))="model_only_needs_datasheet",INDEX(Panels!O:O,MATCH(C9,Panels!C:C,0))="model_only_needs_datasheet"),"VERIFY",IF(INDEX(Panels!F:F,MATCH(C9,Panels!C:C,0))*F9<=INDEX(Inverters!M:M,MATCH(B9,Inverters!C:C,0)),"PASS","FAIL")) | K9: =IF(ISNUMBER(SEARCH("Deye",INDEX(Batteries!M:M,MATCH(D9,Batteries!C:C,0)))),"PASS","VERIFY") | L9: =IF(OR(I9="FAIL",J9="FAIL"),"FAIL",IF(OR(I9="VERIFY",J9="VERIFY",K9="VERIFY",INDEX(Inverters!Q:Q,MATCH(B9,Inverters!C:C,0))="model_only_needs_datasheet",INDEX(Panels!O:O,MATCH(C9,Panels!C:C,0))="model_only_needs_datasheet",INDEX(Batteries!N:N,MATCH(D9,Batteries!C:C,0))="model_only_needs_datasheet"),"VERIFY","PASS")) | M9: Low-voltage starter check.

Sheet Economics
A1: Economics | B1: Value | C1: Unit | D1: Formula / meaning
A2: Region / tariff zone | B2: =Inputs!B25 | D2: From Inputs
A3: Selected panel power | B3: =INDEX(Panels!D:D,MATCH(Inputs!B4,Panels!C:C,0)) | C3: W | D3: From Panels database
A4: Total panel count | B4: =Inputs!B12 | C4: pcs | D4: From Inputs
A5: PV system size | B5: =B3*B4/1000 | C5: kWp | D5: Panel power x total panels
A6: Specific yield | B6: =INDEX(Regions!B:B,MATCH(B2,Regions!A:A,0)) | C6: kWh/kWp/year | D6: From Regions database
A7: Performance ratio | B7: 0.85 | C7: factor | D7: Starter system loss factor
A8: Annual generation | B8: =ROUND(B5*B6*B7,0) | C8: kWh/year | D8: PV size x yield x performance ratio
A9: Retail tariff | B9: =INDEX(Tariffs!B:B,MATCH(B2,Tariffs!A:A,0)) | C9: RUB/kWh | D9: From Tariffs database
A10: Export / green tariff | B10: =INDEX(Tariffs!C:C,MATCH(B2,Tariffs!A:A,0)) | C10: RUB/kWh | D10: Starter microgeneration purchase value
A11: Self-consumption share | B11: =Inputs!B26 | C11: % | D11: From Inputs
A12: Annual savings | B12: =ROUND(B8*(B11/100)*B9+B8*(1-B11/100)*B10,0) | C12: RUB/year | D12: Self-consumed value plus exported value
A13: Simple payback | B13: =IF(B12>0,ROUND(B14/B12,1),"") | C13: years | D13: Installed cost / annual savings
A14: Installed system cost | B14: =Inputs!B27 | C14: RUB | D14: From Inputs
A15: Tariff source status | B15: =Inputs!B28 | D15: VERIFY until supplier/date is checked
A16: Retail tariff source | B16: =INDEX(Tariffs!D:D,MATCH(B2,Tariffs!A:A,0)) | D16: Source URL
A17: Export tariff source | B17: =INDEX(Tariffs!E:E,MATCH(B2,Tariffs!A:A,0)) | D17: Source URL
A18: Monthly consumption | B18: =Inputs!B29 | C18: kWh/month | D18: From Inputs
A19: Annual consumption | B19: =B18*12 | C19: kWh/year | D19: Monthly consumption x 12
A20: Target annual coverage | B20: =B19*Inputs!B30/100 | C20: kWh/year | D20: Annual consumption x target coverage
A21: Day-night blended tariff | B21: =Inputs!B33*(Inputs!B32/100)+Inputs!B34*(1-Inputs!B32/100) | C21: RUB/kWh | D21: Day share x day tariff plus night share x night tariff
A22: Estimated current annual cost | B22: =B19*B9 | C22: RUB/year | D22: Annual consumption x retail tariff
A23: Estimated day-night annual cost | B23: =B19*B21 | C23: RUB/year | D23: Annual consumption x blended day-night tariff
A24: Potential day-night saving before PV | B24: =MAX(0,B22-B23) | C24: RUB/year | D24: Current cost minus day-night cost

Sheet SystemOptions
A1: Option | B1: Quality | C1: Cost per kWp | D1: Service life | E1: Degradation | F1: Required annual generation | G1: Required kWp | H1: Recommended kWp | I1: Panels | J1: Daily generation | K1: Monthly generation | L1: Annual generation | M1: Coverage | N1: Estimated cost | O1: Single-rate savings | P1: Day-night savings | Q1: Green tariff export revenue | R1: Payback day-night | S1: Notes
A2: Premium | B2: =INDEX(OptionTiers!B:B,MATCH(A2,OptionTiers!A:A,0)) | C2: =INDEX(OptionTiers!C:C,MATCH(A2,OptionTiers!A:A,0)) | D2: =INDEX(OptionTiers!D:D,MATCH(A2,OptionTiers!A:A,0)) | E2: =INDEX(OptionTiers!E:E,MATCH(A2,OptionTiers!A:A,0)) | F2: =Economics!B20 | G2: =F2/Economics!B6/Economics!B7 | H2: =ROUNDUP(G2*1000/INDEX(Panels!D:D,MATCH(Inputs!B4,Panels!C:C,0)),0)*INDEX(Panels!D:D,MATCH(Inputs!B4,Panels!C:C,0))/1000 | I2: =ROUNDUP(G2*1000/INDEX(Panels!D:D,MATCH(Inputs!B4,Panels!C:C,0)),0) | J2: =ROUND(L2/365,1) | K2: =ROUND(L2/12,0) | L2: =ROUND(H2*Economics!B6*Economics!B7,0) | M2: =ROUND(L2/Economics!B19*100,0) | N2: =ROUND(H2*C2,0) | O2: =ROUND(L2*(Inputs!B26/100)*Economics!B9+L2*(1-Inputs!B26/100)*Economics!B10,0) | P2: =ROUND(L2*(Inputs!B26/100)*Economics!B21+L2*(1-Inputs!B26/100)*Economics!B10+Economics!B24,0) | Q2: =ROUND(L2*(1-Inputs!B26/100)*Economics!B10,0) | R2: =IF(P2>0,ROUND(N2/P2,1),"") | S2: Higher allowance; verify commercial offer
A3: Standard | B3: =INDEX(OptionTiers!B:B,MATCH(A3,OptionTiers!A:A,0)) | C3: =INDEX(OptionTiers!C:C,MATCH(A3,OptionTiers!A:A,0)) | D3: =INDEX(OptionTiers!D:D,MATCH(A3,OptionTiers!A:A,0)) | E3: =INDEX(OptionTiers!E:E,MATCH(A3,OptionTiers!A:A,0)) | F3: =Economics!B20 | G3: =F3/Economics!B6/Economics!B7 | H3: =ROUNDUP(G3*1000/INDEX(Panels!D:D,MATCH(Inputs!B4,Panels!C:C,0)),0)*INDEX(Panels!D:D,MATCH(Inputs!B4,Panels!C:C,0))/1000 | I3: =ROUNDUP(G3*1000/INDEX(Panels!D:D,MATCH(Inputs!B4,Panels!C:C,0)),0) | J3: =ROUND(L3/365,1) | K3: =ROUND(L3/12,0) | L3: =ROUND(H3*Economics!B6*Economics!B7,0) | M3: =ROUND(L3/Economics!B19*100,0) | N3: =ROUND(H3*C3,0) | O3: =ROUND(L3*(Inputs!B26/100)*Economics!B9+L3*(1-Inputs!B26/100)*Economics!B10,0) | P3: =ROUND(L3*(Inputs!B26/100)*Economics!B21+L3*(1-Inputs!B26/100)*Economics!B10+Economics!B24,0) | Q3: =ROUND(L3*(1-Inputs!B26/100)*Economics!B10,0) | R3: =IF(P3>0,ROUND(N3/P3,1),"") | S3: Balanced default option
